<?xml version="1.0"?>
<robot xmlns:xacro="http://wiki.ros.org/xacro">
  <xacro:include filename="$(find fanuc_resources)/urdf/common_materials.xacro"/>

  <xacro:property name="density" value="1048" />
  <xacro:property name="scaling" value="0.00001" />
  <xacro:property name="dens_scale" value="${density}*${scaling}" />

  <xacro:macro name="fanuc_m900ia260l" params="prefix">
    <!-- links: main serial chain -->
    <link name="${prefix}base_link">
      <visual>
        <origin xyz="0 0 0" rpy="0 0 0"/>
        <geometry>
          <mesh filename="package://fanuc_m900ia_support/meshes/m900ia260l/visual/base_link.stl"/>
        </geometry>
        <xacro:material_fanuc_gray31 />
      </visual>
      <collision>
        <origin xyz="0 0 0" rpy="0 0 0"/>
        <geometry>
          <mesh filename="package://fanuc_m900ia_support/meshes/m900ia260l/collision/base_link.stl"/>
        </geometry>
      </collision>
      <inertial>
        <origin xyz="-0.0479547 0.0005924 0.1838477 " rpy="0 0 0"/>
        <mass value="0.179502640*{density}"/>
        <inertia
          ixx="758.002563*${dens_scale}" ixy="0.059074*${dens_scale}" ixz="-29.833698*${dens_scale}"
          iyy="1059.352539*${dens_scale}" iyz="0.779661*${dens_scale}"
          izz="1392.725098*${dens_scale}"/>
      </inertial>
    </link>
    <link name="${prefix}link_1">
      <visual>
        <origin xyz="0 0 0" rpy="0 0 0"/>
        <geometry>
          <mesh filename="package://fanuc_m900ia_support/meshes/m900ia260l/visual/link_1.stl"/>
        </geometry>
        <xacro:material_fanuc_yellow />
      </visual>
      <collision>
        <origin xyz="0 0 0" rpy="0 0 0"/>
        <geometry>
          <mesh filename="package://fanuc_m900ia_support/meshes/m900ia260l/collision/link_1.stl"/>
        </geometry>
      </collision>
      <inertial>
        <origin xyz="0.2508056 -0.0039480 -0.1876394 " rpy="0 0 0"/>
        <mass value="0.428307129*{density}"/>
        <inertia
          ixx="4593.856934*${dens_scale}" ixy="-51.459423*${dens_scale}" ixz="-767.660156*${dens_scale}"
          iyy="3659.617188*${dens_scale}" iyz="0.543368*${dens_scale}"
          izz="4472.774902*${dens_scale}"/>
      </inertial>
    </link>
    <link name="${prefix}link_2">
      <visual>
        <origin xyz="0 0 0" rpy="0 0 0"/>
        <geometry>
          <mesh filename="package://fanuc_m900ia_support/meshes/m900ia260l/visual/link_2.stl"/>
        </geometry>
        <xacro:material_fanuc_yellow />
      </visual>
      <collision>
        <origin xyz="0 0 0" rpy="0 0 0"/>
        <geometry>
          <mesh filename="package://fanuc_m900ia_support/meshes/m900ia260l/collision/link_2.stl"/>
        </geometry>
      </collision>
      <inertial>
        <origin xyz="0.0208002 -0.0321524 0.4698709 " rpy="0 0 0"/>
        <mass value="0.146323502*{density}"/>
        <inertia
          ixx="1881.386841*${dens_scale}" ixy="-15.604090*${dens_scale}" ixz="29.171331*${dens_scale}"
          iyy="1862.439209*${dens_scale}" iyz="-94.617111*${dens_scale}"
          izz="311.525116*${dens_scale}"/>
      </inertial>
    </link>
    <link name="${prefix}link_3">
      <visual>
        <origin xyz="0 0 0" rpy="0 0 0"/>
        <geometry>
          <mesh filename="package://fanuc_m900ia_support/meshes/m900ia260l/visual/link_3.stl"/>
        </geometry>
        <xacro:material_fanuc_yellow />
      </visual>
      <collision>
        <origin xyz="0 0 0" rpy="0 0 0"/>
        <geometry>
          <mesh filename="package://fanuc_m900ia_support/meshes/m900ia260l/collision/link_3.stl"/>
        </geometry>
      </collision>
      <inertial>
        <origin xyz="0.3940928 -0.0020985 0.1485200" rpy="0 0 0"/>
        <mass value="0.206138123*{density}"/>
        <inertia
          ixx="399.825439*${dens_scale}" ixy="2.884355*${dens_scale}" ixz="-246.776382*${dens_scale}"
          iyy="5650.399902*${dens_scale}" iyz="-2.081667*${dens_scale}"
          izz="5621.276855*${dens_scale}"/>
      </inertial>
    </link>
    <link name="${prefix}link_4">
      <visual>
        <origin xyz="0 0 0" rpy="0 0 0"/>
        <geometry>
          <mesh filename="package://fanuc_m900ia_support/meshes/m900ia260l/visual/link_4.stl"/>
        </geometry>
        <xacro:material_fanuc_yellow />
      </visual>
      <collision>
        <origin xyz="0 0 0" rpy="0 0 0"/>
        <geometry>
          <mesh filename="package://fanuc_m900ia_support/meshes/m900ia260l/collision/link_4.stl"/>
        </geometry>
      </collision>
      <inertial>
        <origin xyz="1.5984120 -0.0070510 -0.0000020" rpy="0 0 0"/>
        <mass value="0.011438374*{density}"/>
        <inertia
          ixx="6.721434*${dens_scale}" ixy="0.585065*${dens_scale}" ixz="-0.000148*${dens_scale}"
          iyy="14.125363*${dens_scale}" iyz="-0.000006*${dens_scale}"
          izz="13.054061*${dens_scale}"/>
      </inertial>
    </link>
    <link name="${prefix}link_5">
      <visual>
        <origin xyz="0 0 0" rpy="0 0 0"/>
        <geometry>
          <mesh filename="package://fanuc_m900ia_support/meshes/m900ia260l/visual/link_5.stl"/>
        </geometry>
        <xacro:material_fanuc_yellow />
      </visual>
      <collision>
        <origin xyz="0 0 0" rpy="0 0 0"/>
        <geometry>
          <mesh filename="package://fanuc_m900ia_support/meshes/m900ia260l/collision/link_5.stl"/>
        </geometry>
      </collision>
      <inertial>
        <origin xyz="0.0419062 -0.0278710 -0.0000007" rpy="0 0 0"/>
        <mass value="0.020431719*{density}"/>
        <inertia
          ixx="22.334682*${dens_scale}" ixy="-2.872280*${dens_scale}" ixz="0.000051*${dens_scale}"
          iyy="24.979155*${dens_scale}" iyz="0.000064*${dens_scale}"
          izz="29.386639*${dens_scale}"/>
      </inertial>
    </link>
    <link name="${prefix}link_6">
      <visual>
        <origin xyz="0 0 0" rpy="0 0 0"/>
        <geometry>
          <mesh filename="package://fanuc_m900ia_support/meshes/m900ia260l/visual/link_6.stl"/>
        </geometry>
        <xacro:material_fanuc_black />
      </visual>
      <collision>
        <origin xyz="0 0 0" rpy="0 0 0"/>
        <geometry>
          <mesh filename="package://fanuc_m900ia_support/meshes/m900ia260l/collision/link_6.stl"/>
        </geometry>
      </collision>
      <inertial>
        <origin xyz="-0.0274942 -0 -0" rpy="0 0 0"/>
        <mass value="0.002406848*{density}"/>
        <inertia
          ixx="1.555723*${dens_scale}" ixy="0*${dens_scale}" ixz="0*${dens_scale}"
          iyy="0.850091*${dens_scale}" iyz="0.0000*${dens_scale}"
          izz="0.850086*${dens_scale}"/>
      </inertial>
    </link>

    <!-- joints: main serial chain -->
    <joint name="${prefix}joint_1" type="revolute">
      <origin xyz="0 0 0.950" rpy="0 0 0"/>
      <parent link="${prefix}base_link"/>
      <child link="${prefix}link_1"/>
      <axis xyz="0 0 1"/>
      <limit lower="-3.141593" upper="3.141593" effort="0" velocity="1.745329" />
    </joint>
    <joint name="${prefix}joint_2" type="revolute">
      <origin xyz="0.370 0 0" rpy="0 0 0"/>
      <parent link="${prefix}link_1"/>
      <child link="${prefix}link_2"/>
      <axis xyz="0 1 0"/>
      <limit lower="-1.308997" upper="1.308997" effort="0" velocity="1.832596" />
    </joint>
    <joint name="${prefix}joint_3" type="revolute">
      <origin xyz="0 0 1.050" rpy="0 0 0"/>
      <parent link="${prefix}link_2"/>
      <child link="${prefix}link_3"/>
      <axis xyz="0 -1 0"/>
      <limit lower="-2.116665" upper="1.570796" effort="0" velocity="1.658063" />
    </joint>
    <joint name="${prefix}joint_4" type="revolute">
      <origin xyz="0 0 0.200" rpy="0 0 0"/>
      <parent link="${prefix}link_3"/>
      <child link="${prefix}link_4"/>
      <axis xyz="-1 0 0"/>
      <limit lower="-6.283185" upper="6.283185" effort="0" velocity="2.094395" />
    </joint>
    <joint name="${prefix}joint_5" type="revolute">
      <origin xyz="1.705 0 0" rpy="0 0 0"/>
      <parent link="${prefix}link_4"/>
      <child link="${prefix}link_5"/>
      <axis xyz="0 -1 0"/>
      <limit lower="-2.181662" upper="2.181662" effort="0" velocity="2.094395" />
    </joint>
    <joint name="${prefix}joint_6" type="revolute">
      <origin xyz="0.270 0 0" rpy="0 0 0"/>
      <parent link="${prefix}link_5"/>
      <child link="${prefix}link_6"/>
      <axis xyz="-1 0 0"/>
      <limit lower="-6.283185" upper="6.283185" effort="0" velocity="3.490658" />
    </joint>

    <!-- parallel bar linkage -->
    <link name="${prefix}plink_1">
      <visual>
        <origin xyz="0 0 0" rpy="0 0 0"/>
        <geometry>
          <mesh filename="package://fanuc_m900ia_support/meshes/m900ia260l/visual/plink_1.stl"/>
        </geometry>
        <xacro:material_fanuc_yellow />
      </visual>
      <collision>
        <origin xyz="0 0 0" rpy="0 0 0"/>
        <geometry>
          <mesh filename="package://fanuc_m900ia_support/meshes/m900ia260l/collision/plink_1.stl"/>
        </geometry>
      </collision>
      <inertial>
        <origin xyz="-0.1043124 -0.0504379 -0.0145418" rpy="0 0 0"/>
        <mass value="0.027578537*{density}"/>
        <inertia
          ixx="32.950230*${dens_scale}" ixy="-1.911048*${dens_scale}" ixz="-1.272046*${dens_scale}"
          iyy="97.812645*${dens_scale}" iyz="0.253856*${dens_scale}"
          izz="73.873703*${dens_scale}"/>
      </inertial>
    </link>
    <link name="${prefix}plink_2">
      <visual>
        <origin xyz="0 0 0" rpy="0 0 0"/>
        <geometry>
          <mesh filename="package://fanuc_m900ia_support/meshes/m900ia260l/visual/plink_2.stl"/>
        </geometry>
        <xacro:material_fanuc_yellow />
      </visual>
      <collision>
        <origin xyz="0 0 0" rpy="0 0 0"/>
        <geometry>
          <mesh filename="package://fanuc_m900ia_support/meshes/m900ia260l/collision/plink_2.stl"/>
        </geometry>
      </collision>
      <inertial>
        <origin xyz="-0.0285391 0.0022351 -0.5422898" rpy="0 0 0"/>
        <mass value="0.012706021*{density}"/>
        <inertia
          ixx="115.503403*${dens_scale}" ixy="-0.027600*${dens_scale}" ixz="-1.782988*${dens_scale}"
          iyy="118.431725*${dens_scale}" iyz="-0.022260*${dens_scale}"
          izz="3.922133*${dens_scale}"/>
      </inertial>
    </link>
    <joint name="${prefix}pjoint_1" type="continuous">
      <origin xyz="0 0.17 0" rpy="0 0 0"/>
      <parent link="${prefix}link_2"/>
      <child link="${prefix}plink_1"/>
      <axis xyz="0 1 0"/>
      <mimic joint="${prefix}joint_3" multiplier="-1" offset="0" />
    </joint>
    <joint name="${prefix}pjoint_2" type="continuous">
      <origin xyz="-0.4 0.096 0" rpy="0 0 0"/>
      <parent link="${prefix}link_3"/>
      <child link="${prefix}plink_2"/>
      <axis xyz="0 1 0"/>
      <mimic joint="${prefix}joint_3" multiplier="1" offset="0" />
    </joint>

    <!-- ROS-Industrial 'base' frame: base_link to Fanuc World Coordinates transform -->
    <link name="${prefix}base" />
    <joint name="${prefix}base_link-base" type="fixed">
      <origin xyz="0 0 0.950" rpy="0 0 0"/>
      <parent link="${prefix}base_link"/>
      <child link="${prefix}base"/>
    </joint>

    <!-- ROS-Industrial 'flange' frame: attachment point for EEF models -->
    <link name="${prefix}flange" />
    <joint name="${prefix}joint_6-flange" type="fixed">
      <origin xyz="0 0 0" rpy="0 0 0" />
      <parent link="${prefix}link_6" />
      <child link="${prefix}flange" />
    </joint>

    <!-- ROS-Industrial 'tool0' frame: all-zeros tool frame -->
    <link name="${prefix}tool0" />
    <joint name="${prefix}link_6-tool0" type="fixed">
      <origin xyz="0 0 0" rpy="${pi} ${-pi/2.0} 0" />
      <parent link="${prefix}flange" />
      <child link="${prefix}tool0" />
    </joint>
  </xacro:macro>
</robot>
