<?xml version="1.0"?>
<robot xmlns:xacro="http://wiki.ros.org/xacro">
  <xacro:include filename="$(find fanuc_resources)/urdf/common_materials.xacro"/>

  <xacro:property name="density" value="1048" />
  <xacro:property name="scaling" value="0.00001" />
  <xacro:property name="dens_scale" value="${density}*${scaling}" />

  <!-- note: we use almost all meshes from the M-710iC/50 as only links 2 and 4 are different. -->
  <xacro:macro name="fanuc_m710ic45m" params="prefix">
    <!-- links: main serial chain -->
    <link name="${prefix}base_link">
      <visual>
        <origin xyz="0 0 0" rpy="0 0 0"/>
        <geometry>
          <mesh filename="package://fanuc_m710ic_support/meshes/m710ic50/visual/base_link.stl"/>
        </geometry>
        <xacro:material_fanuc_black />
      </visual>
      <collision>
        <origin xyz="0 0 0" rpy="0 0 0"/>
        <geometry>
          <mesh filename="package://fanuc_m710ic_support/meshes/m710ic50/collision/base_link.stl"/>
        </geometry>
      </collision>
      <inertial>
        <origin xyz="-0.0494077 -0.0002174 0.1192173 " rpy="0 0 0"/>
        <mass value="0.066986893*{density}"/>
        <inertia
          ixx="178.098145*${dens_scale}" ixy="0.485529*${dens_scale}" ixz="2.748357*${dens_scale}"
          iyy="181.958237*${dens_scale}" iyz="-0.227367*${dens_scale}"
          izz="289.761658*${dens_scale}"/>
      </inertial>
    </link>
    <link name="${prefix}link_1">
      <visual>
        <origin xyz="0 0 0" rpy="0 0 0"/>
        <geometry>
          <mesh filename="package://fanuc_m710ic_support/meshes/m710ic50/visual/link_1.stl"/>
        </geometry>
        <xacro:material_fanuc_yellow />
      </visual>
      <collision>
        <origin xyz="0 0 0" rpy="0 0 0"/>
        <geometry>
          <mesh filename="package://fanuc_m710ic_support/meshes/m710ic50/collision/link_1.stl"/>
        </geometry>
      </collision>
      <inertial>
        <origin xyz="0.0513947 -0.0070627 -0.1050768 " rpy="0 0 0"/>
        <mass value="0.103668549*{density}"/>
        <inertia
          ixx="386.833496*${dens_scale}" ixy="-17.122465*${dens_scale}" ixz="-25.931326*${dens_scale}"
          iyy="329.742950*${dens_scale}" iyz="11.369209*${dens_scale}"
          izz="413.927490*${dens_scale}"/>
      </inertial>
    </link>
    <link name="${prefix}link_2">
      <visual>
        <origin xyz="0 0 0" rpy="0 0 0"/>
        <geometry>
          <mesh filename="package://fanuc_m710ic_support/meshes/m710ic45m/visual/link_2.stl"/>
        </geometry>
        <xacro:material_fanuc_yellow />
      </visual>
      <collision>
        <origin xyz="0 0 0" rpy="0 0 0"/>
        <geometry>
          <mesh filename="package://fanuc_m710ic_support/meshes/m710ic45m/collision/link_2.stl"/>
        </geometry>
      </collision>
      <inertial>
        <origin xyz="0.0025489 0.1553528 0.4616433 " rpy="0 0 0"/>
        <mass value="0.058613258*{density}"/>
        <inertia
          ixx="806.448608*${dens_scale}" ixy="1.348914*${dens_scale}" ixz="0.912000*${dens_scale}"
          iyy="824.407898*${dens_scale}" iyz="-26.071480*${dens_scale}"
          izz="48.607079*${dens_scale}"/>
      </inertial>
    </link>
    <link name="${prefix}link_3">
      <visual>
        <origin xyz="0 0 0" rpy="0 0 0"/>
        <geometry>
          <mesh filename="package://fanuc_m710ic_support/meshes/m710ic50/visual/link_3.stl"/>
        </geometry>
        <xacro:material_fanuc_yellow />
      </visual>
      <collision>
        <origin xyz="0 0 0" rpy="0 0 0"/>
        <geometry>
          <mesh filename="package://fanuc_m710ic_support/meshes/m710ic50/collision/link_3.stl"/>
        </geometry>
      </collision>
      <inertial>
        <origin xyz="0.0223306 -0.0314858 0.0862886 " rpy="0 0 0"/>
        <mass value="0.048697914*{density}"/>
        <inertia
          ixx="93.787186*${dens_scale}" ixy="-9.296334*${dens_scale}" ixz="-13.200597*${dens_scale}"
          iyy="121.645370*${dens_scale}" iyz="-5.063631*${dens_scale}"
          izz="109.984634*${dens_scale}"/>
      </inertial>
    </link>
    <link name="${prefix}link_4">
      <visual>
        <origin xyz="0 0 0" rpy="0 0 0"/>
        <geometry>
          <mesh filename="package://fanuc_m710ic_support/meshes/m710ic45m/visual/link_4.stl"/>
        </geometry>
        <xacro:material_fanuc_yellow />
      </visual>
      <collision>
        <origin xyz="0 0 0" rpy="0 0 0"/>
        <geometry>
          <mesh filename="package://fanuc_m710ic_support/meshes/m710ic45m/collision/link_4.stl"/>
        </geometry>
      </collision>
      <inertial>
        <origin xyz="0.8059817 -0.0208045 0.0004059 " rpy="0 0 0"/>
        <mass value="0.024092754*{density}"/>
        <inertia
          ixx="8.925513*${dens_scale}" ixy="9.760942*${dens_scale}" ixz="-0.090163*${dens_scale}"
          iyy="239.675690*${dens_scale}" iyz="-0.031016*${dens_scale}"
          izz="240.442001*${dens_scale}"/>
      </inertial>
    </link>
    <link name="${prefix}link_5">
      <visual>
        <origin xyz="0 0 0" rpy="0 0 0"/>
        <geometry>
          <mesh filename="package://fanuc_m710ic_support/meshes/m710ic50/visual/link_5.stl"/>
        </geometry>
        <xacro:material_fanuc_yellow />
      </visual>
      <collision>
        <origin xyz="0 0 0" rpy="0 0 0"/>
        <geometry>
          <mesh filename="package://fanuc_m710ic_support/meshes/m710ic50/collision/link_5.stl"/>
        </geometry>
      </collision>
      <inertial>
        <origin xyz="0.0384575 0.0039676 -0 " rpy="0 0 0"/>
        <mass value="0.004812530*{density}"/>
        <inertia
          ixx="1.779768*${dens_scale}" ixy="-0.136643*${dens_scale}" ixz="-0.000000*${dens_scale}"
          iyy="2.552691*${dens_scale}" iyz="0*${dens_scale}"
          izz="2.708632*${dens_scale}"/>
      </inertial>
    </link>
    <link name="${prefix}link_6">
      <visual>
        <origin xyz="0 0 0" rpy="0 0 0"/>
        <geometry>
          <mesh filename="package://fanuc_m710ic_support/meshes/m710ic50/visual/link_6.stl"/>
        </geometry>
        <xacro:material_fanuc_black />
      </visual>
      <collision>
        <origin xyz="0 0 0" rpy="0 0 0"/>
        <geometry>
          <mesh filename="package://fanuc_m710ic_support/meshes/m710ic50/collision/link_6.stl"/>
        </geometry>
      </collision>
      <inertial>
        <origin xyz="-0.0122228 0.0000157 0 " rpy="0 0 0"/>
        <mass value="0.000248562*{density}"/>
        <inertia
          ixx="0.047968*${dens_scale}" ixy="0.000001*${dens_scale}" ixz="0.000000*${dens_scale}"
          iyy="0.024856*${dens_scale}" iyz="0.000000*${dens_scale}"
          izz="0.024850*${dens_scale}"/>
      </inertial>
    </link>

    <!-- joints: main serial chain -->
    <joint name="${prefix}joint_1" type="revolute">
      <origin xyz="0 0 0.565" rpy="0 0 0" />
      <parent link="${prefix}base_link" />
      <child link="${prefix}link_1" />
      <axis xyz="0 0 1" />
      <limit effort="0" lower="${radians(-180)}" upper="${radians(180)}" velocity="${radians(180)}" />
    </joint>
    <joint name="${prefix}joint_2" type="revolute">
      <origin xyz="0.150 0 0" rpy="0 0 0"/>
      <parent link="${prefix}link_1" />
      <child link="${prefix}link_2" />
      <axis xyz="0 1 0" />
      <limit effort="0" lower="${radians(-90)}" upper="${radians(135)}" velocity="${radians(180)}" />
    </joint>
    <joint name="${prefix}joint_3" type="revolute">
      <origin xyz="0 0 1.150" rpy="0 0 0"/>
      <parent link="${prefix}link_2" />
      <child link="${prefix}link_3" />
      <axis xyz="0 -1 0" />
      <limit effort="0" lower="${radians(-160)}" upper="${radians(280)}" velocity="${radians(180)}" />
    </joint>
    <joint name="${prefix}joint_4" type="revolute">
      <origin xyz="0 0 0.170" rpy="0 0 0"/>
      <parent link="${prefix}link_3"/>
      <child link="${prefix}link_4"/>
      <axis xyz="-1 0 0"/>
      <limit effort="0" lower="${radians(-400)}" upper="${radians(400)}" velocity="${radians(250)}" />
    </joint>
    <joint name="${prefix}joint_5" type="revolute">
      <origin xyz="1.295 0 0" rpy="0 0 0"/>
      <parent link="${prefix}link_4"/>
      <child link="${prefix}link_5"/>
      <axis xyz="0 -1 0"/>
      <limit effort="0" lower="${radians(-125)}" upper="${radians(125)}" velocity="${radians(250)}" />
    </joint>
    <joint name="${prefix}joint_6" type="revolute">
      <origin xyz="0.175 0 0" rpy="0 0 0"/>
      <parent link="${prefix}link_5"/>
      <child link="${prefix}link_6"/>
      <axis xyz="-1 0 0"/>
      <limit effort="0" lower="${radians(-400)}" upper="${radians(400)}" velocity="${radians(360)}" />
    </joint>

    <!-- ROS-Industrial 'base' frame: base_link to Fanuc World Coordinates transform -->
    <link name="${prefix}base" />
    <joint name="${prefix}base_link-base" type="fixed">
      <origin xyz="0 0 0.565" rpy="0 0 0"/>
      <parent link="${prefix}base_link"/>
      <child link="${prefix}base"/>
    </joint>

    <!-- ROS-Industrial 'flange' frame: attachment point for EEF models -->
    <link name="${prefix}flange" />
    <joint name="${prefix}joint_6-flange" type="fixed">
      <origin xyz="0 0 0" rpy="0 0 0" />
      <parent link="${prefix}link_6" />
      <child link="${prefix}flange" />
    </joint>

    <!-- ROS-Industrial 'tool0' frame: all-zeros tool frame -->
    <link name="${prefix}tool0" />
    <joint name="${prefix}link_6-tool0" type="fixed">
      <origin xyz="0 0 0" rpy="${pi} ${-pi/2.0} 0" />
      <parent link="${prefix}flange" />
      <child link="${prefix}tool0" />
    </joint>
  </xacro:macro>
</robot>
